Workbook

Sheet 00_Resumo
A1: 01 - Estimativa de Custos das Intervenções Estruturais
A2: Volume | B2: Id | C2: Grau | D2: Bairro | E2: Alto | G2: Contenções e Demolições | L2: Obras Complementares | R2: Subtotal 1 | S2: Subtotal 2 | U2: Subtotal 3 | W2: Valores Adicionais (%) | AC2: Subtotal 4 | AD2: Subtotal 5 | AE2: Subtotal 4 + Subtotal 5 | AG2: BDI (26,8%) | AI2: Subtotal 6 | AJ2: Subtotal 7 | AL2: Custo Total | AN2: Custo Por Domicílio
G3: Número de Domicílios | H3: Número de Domicílios - Soma | J3: Custo Estimado das Obras | L3: Custo Estimado dos Serviços Preliminares / Demolições / Limpeza | M3: Custo Estimado das Obras de Drenagem | N3: Custo Estimado das Obras de Mobilidade | O3: Custo Estimado das Obras de Esgoto | P3: Custo Estimado das Obras de Obras De Rsu | R3: Contenções e Demolições | S3: Obras Complementares | U3: =_xlfn.CONCAT(R3," ","+"," ",S3) -> Contenções e Demolições + Obras Complementares | W3: Projeto executivo, levantamentos, ensaios e estudos (5%) | X3: Serviços preliminares (limpeza do terreno, tapume e canteiro) (4%) | Y3: Equipamentos de monitoramento e alerta (1%) | Z3: Ações sociais e trabalho social (3%) | AA3: Avaliação pós-intervenção e ocupação (0,5%) | AC3: Subtotal 1 + Adicionais % | AD3: Subtotal 2 + Adicionais % | AI3: Subtotal 4 + BDI | AJ3: Subtotal 5 + BDI | AL3: Subtotal 6 + Subtotal 7
AC4: =_xlfn.CONCAT(R3," ","+"," ","Adicionais %") -> Contenções e Demolições + Adicionais % | AD4: =_xlfn.CONCAT(S3," ","+"," ","Adicionais %") -> Obras Complementares + Adicionais % | AE4: =_xlfn.CONCAT(R3," ","+"," ",S3," ","+"," ","Adicionais %") -> Contenções e Demolições + Obras Complementares + Adicionais % | AI4: =_xlfn.CONCAT(AC4," ","+"," ","BDI") -> Contenções e Demolições + Adicionais % + BDI | AJ4: =_xlfn.CONCAT(AD4," ","+"," ","BDI") -> Obras Complementares + Adicionais % + BDI | AL4: =_xlfn.CONCAT(R3," ","+"," ",S3," ","+"," ","Adicionais %"," ","+"," ","BDI") -> Contenções e Demolições + Obras Complementares + Adicionais % + BDI
A5: 1 | B5: =MID('01_Carvalho'!D5,16,6) -> A1S1R3 | C5: =RIGHT(B5,2) -> R3 | D5: =MID('01_Carvalho'!$C$3,51,9) -> Esperança | E5: =MID('01_Carvalho'!$C$3,34,8) -> Carvalho | G5: 6 | J5: ='01_Carvalho'!M5 -> 386572.95 | L5: =0 -> 0 | M5: 0 | N5: 0 | O5: 0 | P5: 0 | R5: =SUM(J5:J5) -> 386572.95 | S5: =SUM(L5:P5) -> 0 | U5: =R5+S5 -> 386572.95 | W5: =U5*0.05 -> 19328.648 | X5: =U5*0.04 -> 15462.918 | Y5: =U5*0.01 -> 3865.7295 | Z5: =U5*0.03 -> 11597.189 | AA5: =U5*0.005 -> 1932.8648 | AC5: =R5+SUM(W5:AA5) -> 438760.3 | AD5: 0 | AE5: =SUM(AC5:AD5) -> 438760.3 | AG5: =AE5*0.268 -> 117587.76 | AI5: =AC5+AC5*0.268 -> 556348.06 | AJ5: =AD5+AD5*0.268 -> 0 | AL5: =SUM(AI5:AJ5) -> 556348.06 | AN5: =AL5/G5 -> 92724.676
A6: 1 | B6: =MID('01_Carvalho'!D36,16,6) -> A1S2R4 | C6: =RIGHT(B6,2) -> R4 | D6: =MID('01_Carvalho'!$C$3,51,9) -> Esperança | E6: =MID('01_Carvalho'!$C$3,34,8) -> Carvalho | G6: 17 | J6: ='01_Carvalho'!M36 -> 743321.27 | L6: =0 -> 0 | M6: 0 | N6: 0 | O6: 0 | P6: 0 | R6: =SUM(J6:J6) -> 743321.27 | S6: =SUM(L6:P6) -> 0 | U6: =R6+S6 -> 743321.27 | W6: =U6*0.05 -> 37166.064 | X6: =U6*0.04 -> 29732.851 | Y6: =U6*0.01 -> 7433.2127 | Z6: =U6*0.03 -> 22299.638 | AA6: =U6*0.005 -> 3716.6064 | AC6: =R6+SUM(W6:AA6) -> 843669.64 | AD6: 0 | AE6: =SUM(AC6:AD6) -> 843669.64 | AG6: =AE6*0.268 -> 226103.46 | AI6: =AC6+AC6*0.268 -> 1069773.1 | AJ6: =AD6+AD6*0.268 -> 0 | AL6: =SUM(AI6:AJ6) -> 1069773.1 | AN6: =AL6/G6 -> 62927.83
A7: 1 | B7: =MID('01_Carvalho'!$D$67,16,6) -> A4S1R3 | C7: =RIGHT(B7,2) -> R3 | D7: =MID('01_Carvalho'!$C$3,51,9) -> Esperança | E7: =MID('01_Carvalho'!$C$3,34,8) -> Carvalho | G7: 24 | J7: ='01_Carvalho'!M67 -> 357741.8 | L7: =0 -> 0 | M7: 0 | N7: 0 | O7: 0 | P7: 0 | R7: =SUM(J7:J7) -> 357741.8 | S7: =SUM(L7:P7) -> 0 | U7: =R7+S7 -> 357741.8 | W7: =U7*0.05 -> 17887.09 | X7: =U7*0.04 -> 14309.672 | Y7: =U7*0.01 -> 3577.418 | Z7: =U7*0.03 -> 10732.254 | AA7: =U7*0.005 -> 1788.709 | AC7: =R7+SUM(W7:AA7) -> 406036.94 | AD7: 0 | AE7: =SUM(AC7:AD7) -> 406036.94 | AG7: =AE7*0.268 -> 108817.9 | AI7: =AC7+AC7*0.268 -> 514854.84 | AJ7: =AD7+AD7*0.268 -> 0 | AL7: =SUM(AI7:AJ7) -> 514854.84 | AN7: =AL7/G7 -> 21452.285
A8: 1 | B8: =MID('01_Carvalho'!$D$87,16,6) -> A4S2R4 | C8: =RIGHT(B8,2) -> R4 | D8: =MID('01_Carvalho'!$C$3,51,9) -> Esperança | E8: =MID('01_Carvalho'!$C$3,34,8) -> Carvalho | G8: 24 | J8: ='01_Carvalho'!M87 -> 171290.91 | L8: =0 -> 0 | M8: 0 | N8: 0 | O8: 0 | P8: 0 | R8: =SUM(J8:J8) -> 171290.91 | S8: =SUM(L8:P8) -> 0 | U8: =R8+S8 -> 171290.91 | W8: =U8*0.05 -> 8564.5455 | X8: =U8*0.04 -> 6851.6364 | Y8: =U8*0.01 -> 1712.9091 | Z8: =U8*0.03 -> 5138.7273 | AA8: =U8*0.005 -> 856.45455 | AC8: =R8+SUM(W8:AA8) -> 194415.18 | AD8: 0 | AE8: =SUM(AC8:AD8) -> 194415.18 | AG8: =AE8*0.268 -> 52103.269 | AI8: =AC8+AC8*0.268 -> 246518.45 | AJ8: =AD8+AD8*0.268 -> 0 | AL8: =SUM(AI8:AJ8) -> 246518.45 | AN8: =AL8/G8 -> 10271.602
A9: 1 | B9: =MID('01_Carvalho'!$D$125,16,6) -> A5S2R3 | C9: =RIGHT(B9,2) -> R3 | D9: =MID('01_Carvalho'!$C$3,51,9) -> Esperança | E9: =MID('01_Carvalho'!$C$3,34,8) -> Carvalho | G9: 35 | J9: ='01_Carvalho'!M125 -> 246744.4 | L9: =0 -> 0 | M9: 0 | N9: 0 | O9: 0 | P9: 0 | R9: =SUM(J9:J9) -> 246744.4 | S9: =SUM(L9:P9) -> 0 | U9: =R9+S9 -> 246744.4 | W9: =U9*0.05 -> 12337.22 | X9: =U9*0.04 -> 9869.776 | Y9: =U9*0.01 -> 2467.444 | Z9: =U9*0.03 -> 7402.332 | AA9: =U9*0.005 -> 1233.722 | AC9: =R9+SUM(W9:AA9) -> 280054.89 | AD9: 0 | AE9: =SUM(AC9:AD9) -> 280054.89 | AG9: =AE9*0.268 -> 75054.712 | AI9: =AC9+AC9*0.268 -> 355109.61 | AJ9: =AD9+AD9*0.268 -> 0 | AL9: =SUM(AI9:AJ9) -> 355109.61 | AN9: =AL9/G9 -> 10145.989
A10: 1 | B10: - | C10: - | D10: =MID('01_Carvalho'!$C$3,51,9) -> Esperança | E10: =MID('01_Carvalho'!$C$3,34,8) -> Carvalho | H10: =SUM(G5:G9) -> 106 | J10: 0 | L10: =0 -> 0 | M10: ='01_Carvalho'!J143 -> 49097.71 | N10: ='01_Carvalho'!J148 -> 429182.43 | O10: ='01_Carvalho'!J168 -> 10287.16 | P10: ='01_Carvalho'!J171 -> 7816 | R10: 0 | S10: =SUM(L10:P10) -> 496383.3 | U10: =R10+S10 -> 496383.3 | W10: =U10*0.05 -> 24819.165 | X10: =U10*0.04 -> 19855.332 | Y10: =U10*0.01 -> 4963.833 | Z10: =U10*0.03 -> 14891.499 | AA10: =U10*0.005 -> 2481.9165 | AC10: 0 | AD10: =S10+SUM(W10:AA10) -> 563395.05 | AE10: =SUM(AC10:AD10) -> 563395.05 | AG10: =AE10*0.268 -> 150989.87 | AI10: =AC10+AC10*0.268 -> 0 | AJ10: =AD10+AD10*0.268 -> 714384.92 | AL10: =SUM(AI10:AJ10) -> 714384.92 | AN10: =AL10/H10 -> 6739.4804
A12: 1 | B12: =MID('02_Esperança'!$B$5,16,6) -> A1S2R4 | C12: =RIGHT(B12,2) -> R4 | D12: =MID('02_Esperança'!$A$3,51,10) -> Esperança | E12: =MID('02_Esperança'!$A$3,34,9) -> Esperança | G12: 76 | J12: ='02_Esperança'!K5 -> 99348.32 | L12: 0 | M12: 0 | N12: 0 | O12: 0 | P12: 0 | R12: =SUM(J12:J12) -> 99348.32 | S12: =SUM(M12:P12) -> 0 | U12: =R12+S12 -> 99348.32 | W12: =U12*0.05 -> 4967.416 | X12: =U12*0.04 -> 3973.9328 | Y12: =U12*0.01 -> 993.4832 | Z12: =U12*0.03 -> 2980.4496 | AA12: =U12*0.005 -> 496.7416 | AC12: =R12+SUM(W12:AA12) -> 112760.34 | AD12: 0 | AE12: =SUM(AC12:AD12) -> 112760.34 | AG12: =AE12*0.268 -> 30219.772 | AI12: =AC12+AC12*0.268 -> 142980.12 | AJ12: =AD12+AD12*0.268 -> 0 | AL12: =SUM(AI12:AJ12) -> 142980.12 | AN12: =AL12/G12 -> 1881.3173
A13: 1 | B13: =MID('02_Esperança'!$B$36,16,6) -> A1S3R3 | C13: =RIGHT(B13,2) -> R3 | D13: =MID('02_Esperança'!$A$3,51,10) -> Esperança | E13: =MID('02_Esperança'!$A$3,34,9) -> Esperança | G13: 40 | J13: ='02_Esperança'!K36 -> 1422949.4 | L13: 0 | M13: 0 | N13: 0 | O13: 0 | P13: 0 | R13: =SUM(J13:J13) -> 1422949.4 | S13: =SUM(M13:P13) -> 0 | U13: =R13+S13 -> 1422949.4 | W13: =U13*0.05 -> 71147.47 | X13: =U13*0.04 -> 56917.976 | Y13: =U13*0.01 -> 14229.494 | Z13: =U13*0.03 -> 42688.482 | AA13: =U13*0.005 -> 7114.747 | AC13: =R13+SUM(W13:AA13) -> 1615047.6 | AD13: 0 | AE13: =SUM(AC13:AD13) -> 1615047.6 | AG13: =AE13*0.268 -> 432832.75 | AI13: =AC13+AC13*0.268 -> 2047880.3 | AJ13: =AD13+AD13*0.268 -> 0 | AL13: =SUM(AI13:AJ13) -> 2047880.3 | AN13: =AL13/G13 -> 51197.008
A14: 1 | B14: =MID('02_Esperança'!$B$74,16,6) -> A2S1R3 | C14: =RIGHT(B14,2) -> R3 | D14: =MID('02_Esperança'!$A$3,51,10) -> Esperança | E14: =MID('02_Esperança'!$A$3,34,9) -> Esperança | G14: 63 | J14: ='02_Esperança'!K74 -> 2394136.9 | L14: 0 | M14: 0 | N14: 0 | O14: 0 | P14: 0 | R14: =SUM(J14:J14) -> 2394136.9 | S14: =SUM(M14:P14) -> 0 | U14: =R14+S14 -> 2394136.9 | W14: =U14*0.05 -> 119706.85 | X14: =U14*0.04 -> 95765.476 | Y14: =U14*0.01 -> 23941.369 | Z14: =U14*0.03 -> 71824.107 | AA14: =U14*0.005 -> 11970.684 | AC14: =R14+SUM(W14:AA14) -> 2717345.4 | AD14: 0 | AE14: =SUM(AC14:AD14) -> 2717345.4 | AG14: =AE14*0.268 -> 728248.56 | AI14: =AC14+AC14*0.268 -> 3445593.9 | AJ14: =AD14+AD14*0.268 -> 0 | AL14: =SUM(AI14:AJ14) -> 3445593.9 | AN14: =AL14/G14 -> 54691.967
A15: 1 | B15: =MID('02_Esperança'!$B$132,16,6) -> A4S1R3 | C15: =RIGHT(B15,2) -> R3 | D15: =MID('02_Esperança'!$A$3,51,10) -> Esperança | E15: =MID('02_Esperança'!$A$3,34,9) -> Esperança | G15: 44 | J15: ='02_Esperança'!K132 -> 1647346.8 | L15: 0 | M15: 0 | N15: 0 | O15: 0 | P15: 0 | R15: =SUM(J15:J15) -> 1647346.8 | S15: =SUM(M15:P15) -> 0 | U15: =R15+S15 -> 1647346.8 | W15: =U15*0.05 -> 82367.339 | X15: =U15*0.04 -> 65893.871 | Y15: =U15*0.01 -> 16473.468 | Z15: =U15*0.03 -> 49420.403 | AA15: =U15*0.005 -> 8236.7339 | AC15: =R15+SUM(W15:AA15) -> 1869738.6 | AD15: 0 | AE15: =SUM(AC15:AD15) -> 1869738.6 | AG15: =AE15*0.268 -> 501089.94 | AI15: =AC15+AC15*0.268 -> 2370828.5 | AJ15: =AD15+AD15*0.268 -> 0 | AL15: =SUM(AI15:AJ15) -> 2370828.5 | AN15: =AL15/G15 -> 53882.467
A16: 1 | B16: - | C16: =RIGHT(B16,2) -> - | D16: =MID('02_Esperança'!$A$3,51,10) -> Esperança | E16: =MID('02_Esperança'!$A$3,34,9) -> Esperança | H16: =SUM(G12:G15) -> 223 | J16: 0 | L16: ='02_Esperança'!H164 -> 121034.78 | M16: ='02_Esperança'!H177 -> 84077.4 | N16: ='02_Esperança'!H182 -> 1791988.5 | O16: ='02_Esperança'!H202 -> 36357.36 | P16: ='02_Esperança'!H205 -> 7316 | R16: =SUM(J16:J16) -> 0 | S16: =SUM(L16:P16) -> 2040774.1 | U16: =R16+S16 -> 2040774.1 | W16: =U16*0.05 -> 102038.7 | X16: =U16*0.04 -> 81630.963 | Y16: =U16*0.01 -> 20407.741 | Z16: =U16*0.03 -> 61223.222 | AA16: =U16*0.005 -> 10203.87 | AC16: 0 | AD16: =S16+SUM(W16:AA16) -> 2316278.6 | AE16: =SUM(AC16:AD16) -> 2316278.6 | AG16: =AE16*0.268 -> 620762.66 | AI16: =AC16+AC16*0.268 -> 0 | AJ16: =AD16+AD16*0.268 -> 2937041.2 | AL16: =SUM(AI16:AJ16) -> 2937041.2 | AN16: =AL16/H16 -> 13170.589
A18: 1 | B18: =MID('03_Aureliano'!$B$5,16,6) -> A1S1R4 | C18: =RIGHT(B18,2) -> R4 | D18: =MID('03_Aureliano'!$A$3,49,9) -> Esperança | E18: =MID('03_Aureliano'!$A$3,31,9) -> Aureliano | G18: 58 | J18: ='03_Aureliano'!K5 -> 3705680.7 | L18: 0 | M18: 0 | N18: 0 | O18: 0 | P18: 0 | R18: =SUM(J18:J18) -> 3705680.7 | S18: =SUM(L18:P18) -> 0 | U18: =R18+S18 -> 3705680.7 | W18: =U18*0.05 -> 185284.04 | X18: =U18*0.04 -> 148227.23 | Y18: =U18*0.01 -> 37056.807 | Z18: =U18*0.03 -> 111170.42 | AA18: =U18*0.005 -> 18528.404 | AC18: =R18+SUM(W18:AA18) -> 4205947.6 | AD18: 0 | AE18: =SUM(AC18:AD18) -> 4205947.6 | AG18: =AE18*0.268 -> 1127194 | AI18: =AC18+AC18*0.268 -> 5333141.6 | AJ18: =AD18+AD18*0.268 -> 0 | AL18: =SUM(AI18:AJ18) -> 5333141.6 | AN18: =AL18/G18 -> 91950.717
A19: 1 | B19: =MID('03_Aureliano'!$B$63,16,6) -> A2S1R3 | C19: =RIGHT(B19,2) -> R3 | D19: =MID('03_Aureliano'!$A$3,49,9) -> Esperança | E19: =MID('03_Aureliano'!$A$3,31,9) -> Aureliano | G19: 22 | J19: ='03_Aureliano'!K63 -> 1052807.1 | L19: 0 | M19: 0 | N19: 0 | O19: 0 | P19: 0 | R19: =SUM(J19:J19) -> 1052807.1 | S19: =SUM(L19:P19) -> 0 | U19: =R19+S19 -> 1052807.1 | W19: =U19*0.05 -> 52640.356 | X19: =U19*0.04 -> 42112.284 | Y19: =U19*0.01 -> 10528.071 | Z19: =U19*0.03 -> 31584.213 | AA19: =U19*0.005 -> 5264.0356 | AC19: =R19+SUM(W19:AA19) -> 1194936.1 | AD19: 0 | AE19: =SUM(AC19:AD19) -> 1194936.1 | AG19: =AE19*0.268 -> 320242.87 | AI19: =AC19+AC19*0.268 -> 1515178.9 | AJ19: =AD19+AD19*0.268 -> 0 | AL19: =SUM(AI19:AJ19) -> 1515178.9 | AN19: =AL19/G19 -> 68871.77
A20: 1 | B20: =MID('03_Aureliano'!$B$92,16,6) -> A2S3R3 | C20: =RIGHT(B20,2) -> R3 | D20: =MID('03_Aureliano'!$A$3,49,9) -> Esperança | E20: =MID('03_Aureliano'!$A$3,31,9) -> Aureliano | G20: 31 | J20: ='03_Aureliano'!K92 -> 473053.69 | L20: 0 | M20: 0 | N20: 0 | O20: 0 | P20: 0 | R20: =SUM(J20:J20) -> 473053.69 | S20: =SUM(L20:P20) -> 0 | U20: =R20+S20 -> 473053.69 | W20: =U20*0.05 -> 23652.684 | X20: =U20*0.04 -> 18922.148 | Y20: =U20*0.01 -> 4730.5369 | Z20: =U20*0.03 -> 14191.611 | AA20: =U20*0.005 -> 2365.2684 | AC20: =R20+SUM(W20:AA20) -> 536915.94 | AD20: 0 | AE20: =SUM(AC20:AD20) -> 536915.94 | AG20: =AE20*0.268 -> 143893.47 | AI20: =AC20+AC20*0.268 -> 680809.41 | AJ20: =AD20+AD20*0.268 -> 0 | AL20: =SUM(AI20:AJ20) -> 680809.41 | AN20: =AL20/G20 -> 21961.594
H21: =SUM(G18:G20) -> 111 | J21: 0 | L21: ='03_Aureliano'!H120 -> 105476.46 | M21: ='03_Aureliano'!H133 -> 1018718.2 | N21: ='03_Aureliano'!H141 -> 333735.71 | O21: ='03_Aureliano'!H145 -> 44671.64 | P21: 0 | R21: =SUM(J21:J21) -> 0 | S21: =SUM(L21:P21) -> 1502602 | U21: =R21+S21 -> 1502602 | W21: =U21*0.05 -> 75130.099 | X21: =U21*0.04 -> 60104.079 | Y21: =U21*0.01 -> 15026.02 | Z21: =U21*0.03 -> 45078.059 | AA21: =U21*0.005 -> 7513.0099 | AC21: 0 | AD21: =S21+SUM(W21:AA21) -> 1705453.2 | AE21: =SUM(AC21:AD21) -> 1705453.2 | AG21: =AE21*0.268 -> 457061.47 | AI21: =AC21+AC21*0.268 -> 0 | AJ21: =AD21+AD21*0.268 -> 2162514.7 | AL21: =SUM(AI21:AJ21) -> 2162514.7 | AN21: =AL21/H21 -> 19482.114
A23: 1 | B23: =MID('04_Seringal'!$B$5,16,6) -> A2S1R3 | C23: =RIGHT(B23,2) -> R3 | D23: =MID('04_Seringal'!$A$3,51,9) -> Esperança | E23: =MID('04_Seringal'!$A$3,34,9) -> Seringal | G23: 30 | J23: ='04_Seringal'!K5 -> 459537.89 | L23: 0 | M23: 0 | N23: 0 | O23: 0 | P23: 0 | R23: =SUM(J23:J23) -> 459537.89 | S23: =SUM(L23:P23) -> 0 | U23: =R23+S23 -> 459537.89 | W23: =U23*0.05 -> 22976.895 | X23: =U23*0.04 -> 18381.516 | Y23: =U23*0.01 -> 4595.3789 | Z23: =U23*0.03 -> 13786.137 | AA23: =U23*0.005 -> 2297.6895 | AC23: =R23+SUM(W23:AA23) -> 521575.51 | AD23: 0 | AE23: =SUM(AC23:AD23) -> 521575.51 | AG23: =AE23*0.268 -> 139782.24 | AI23: =AC23+AC23*0.268 -> 661357.74 | AJ23: =AD23+AD23*0.268 -> 0 | AL23: =SUM(AI23:AJ23) -> 661357.74 | AN23: =AL23/G23 -> 22045.258
A24: 1 | B24: =MID('04_Seringal'!$B$32,16,6) -> A3S1R4 | C24: =RIGHT(B24,2) -> R4 | D24: =MID('04_Seringal'!$A$3,51,9) -> Esperança | E24: =MID('04_Seringal'!$A$3,34,9) -> Seringal | G24: 83 | J24: ='04_Seringal'!K32 -> 2170818.4 | L24: 0 | M24: 0 | N24: 0 | O24: 0 | P24: 0 | R24: =SUM(J24:J24) -> 2170818.4 | S24: =SUM(L24:P24) -> 0 | U24: =R24+S24 -> 2170818.4 | W24: =U24*0.05 -> 108540.92 | X24: =U24*0.04 -> 86832.737 | Y24: =U24*0.01 -> 21708.184 | Z24: =U24*0.03 -> 65124.553 | AA24: =U24*0.005 -> 10854.092 | AC24: =R24+SUM(W24:AA24) -> 2463878.9 | AD24: 0 | AE24: =SUM(AC24:AD24) -> 2463878.9 | AG24: =AE24*0.268 -> 660319.55 | AI24: =AC24+AC24*0.268 -> 3124198.5 | AJ24: =AD24+AD24*0.268 -> 0 | AL24: =SUM(AI24:AJ24) -> 3124198.5 | AN24: =AL24/G24 -> 37640.945
H25: =SUM(G23:G24) -> 113 | J25: ='03_Aureliano'!K12 -> 0 | L25: ='04_Seringal'!H131 -> 26057.63 | M25: ='04_Seringal'!H95 -> 203825.04 | N25: ='04_Seringal'!H103 -> 150790.72 | O25: ='04_Seringal'!H123 -> 21560.76 | P25: ='04_Seringal'!H126 -> 11224 | R25: =SUM(J25:J25) -> 0 | S25: =SUM(L25:P25) -> 413458.15 | U25: =R25+S25 -> 413458.15 | W25: =U25*0.05 -> 20672.907 | X25: =U25*0.04 -> 16538.326 | Y25: =U25*0.01 -> 4134.5815 | Z25: =U25*0.03 -> 12403.744 | AA25: =U25*0.005 -> 2067.2907 | AC25: 0 | AD25: =S25+SUM(W25:AA25) -> 469275 | AE25: =SUM(AC25:AD25) -> 469275 | AG25: =AE25*0.268 -> 125765.7 | AI25: =AC25+AC25*0.268 -> 0 | AJ25: =AD25+AD25*0.268 -> 595040.7 | AL25: =SUM(AI25:AJ25) -> 595040.7 | AN25: =AL25/H25 -> 5265.8469
A27: 1 | B27: =MID('05_Vila Freitas'!$B$5,16,6) -> A1S1R3 | C27: =RIGHT(B27,2) -> R3 | D27: =MID('05_Vila Freitas'!$A$3,52,9) -> Esperança | E27: =MID('05_Vila Freitas'!$A$3,31,12) -> Vila Freitas | G27: 85 | J27: ='05_Vila Freitas'!K5 -> 800252.69 | L27: 0 | M27: 0 | N27: 0 | O27: 0 | P27: 0 | R27: =SUM(J27:J27) -> 800252.69 | S27: =SUM(L27:P27) -> 0 | U27: =R27+S27 -> 800252.69 | W27: =U27*0.05 -> 40012.635 | X27: =U27*0.04 -> 32010.108 | Y27: =U27*0.01 -> 8002.5269 | Z27: =U27*0.03 -> 24007.581 | AA27: =U27*0.005 -> 4001.2635 | AC27: =R27+SUM(W27:AA27) -> 908286.81 | AD27: 0 | AE27: =SUM(AC27:AD27) -> 908286.81 | AG27: =AE27*0.268 -> 243420.86 | AI27: =AC27+AC27*0.268 -> 1151707.7 | AJ27: =AD27+AD27*0.268 -> 0 | AL27: =SUM(AI27:AJ27) -> 1151707.7 | AN27: =AL27/G27 -> 13549.502
H28: =G27 -> 85 | J28: ='03_Aureliano'!K15 -> 0 | L28: 0 | M28: ='05_Vila Freitas'!H40 -> 475239.53 | N28: ='05_Vila Freitas'!H48 -> 495930.39 | O28: ='05_Vila Freitas'!H54 -> 31269 | P28: ='05_Vila Freitas'!H57 -> 24092 | R28: =SUM(J28:J28) -> 0 | S28: =SUM(L28:P28) -> 1026530.9 | U28: =R28+S28 -> 1026530.9 | W28: =U28*0.05 -> 51326.546 | X28: =U28*0.04 -> 41061.237 | Y28: =U28*0.01 -> 10265.309 | Z28: =U28*0.03 -> 30795.927 | AA28: =U28*0.005 -> 5132.6546 | AC28: 0 | AD28: =S28+SUM(W28:AA28) -> 1165112.6 | AE28: =SUM(AC28:AD28) -> 1165112.6 | AG28: =AE28*0.268 -> 312250.17 | AI28: =AC28+AC28*0.268 -> 0 | AJ28: =AD28+AD28*0.268 -> 1477362.8 | AL28: =SUM(AI28:AJ28) -> 1477362.8 | AN28: =AL28/H28 -> 17380.738
A30: 1 | B30: =MID('06_Nova Esperança'!$B$5,16,6) -> A1S1R3 | C30: =RIGHT(B30,2) -> R3 | D30: =MID('06_Nova Esperança'!$A$3,54,9) -> Esperança | E30: =MID('06_Nova Esperança'!$A$3,31,14) -> Nova Esperança | G30: 48 | J30: ='06_Nova Esperança'!K5 -> 1071693.6 | L30: 0 | M30: 0 | N30: 0 | O30: 0 | P30: 0 | R30: =SUM(J30:J30) -> 1071693.6 | S30: =SUM(L30:P30) -> 0 | U30: =R30+S30 -> 1071693.6 | W30: =U30*0.05 -> 53584.68 | X30: =U30*0.04 -> 42867.744 | Y30: =U30*0.01 -> 10716.936 | Z30: =U30*0.03 -> 32150.808 | AA30: =U30*0.005 -> 5358.468 | AC30: =R30+SUM(W30:AA30) -> 1216372.2 | AD30: 0 | AE30: =SUM(AC30:AD30) -> 1216372.2 | AG30: =AE30*0.268 -> 325987.76 | AI30: =AC30+AC30*0.268 -> 1542360 | AJ30: =AD30+AD30*0.268 -> 0 | AL30: =SUM(AI30:AJ30) -> 1542360 | AN30: =AL30/G30 -> 32132.5
H31: =G30 -> 48 | J31: 0 | L31: 0 | M31: ='06_Nova Esperança'!H40 -> 207217.88 | N31: 0 | O31: 0 | P31: ='06_Nova Esperança'!H48 -> 5706 | R31: =SUM(J31:J31) -> 0 | S31: =SUM(L31:P31) -> 212923.88 | U31: =R31+S31 -> 212923.88 | W31: =U31*0.05 -> 10646.194 | X31: =U31*0.04 -> 8516.9551 | Y31: =U31*0.01 -> 2129.2388 | Z31: =U31*0.03 -> 6387.7163 | AA31: =U31*0.005 -> 1064.6194 | AC31: 0 | AD31: =S31+SUM(W31:AA31) -> 241668.6 | AE31: =SUM(AC31:AD31) -> 241668.6 | AG31: =AE31*0.268 -> 64767.185 | AI31: =AC31+AC31*0.268 -> 0 | AJ31: =AD31+AD31*0.268 -> 306435.79 | AL31: =SUM(AI31:AJ31) -> 306435.79 | AN31: =AL31/H31 -> 6384.0789
A33: 1 | B33: =MID('07_Floresta'!$B$5,16,6) -> A4S2R3 | C33: =RIGHT(B33,2) -> R3 | D33: =MID('07_Floresta'!$A$3,51,7) -> Malhado | E33: =MID('07_Floresta'!$A$3,34,8) -> Floresta | G33: 15 | J33: ='07_Floresta'!K5 -> 504489.82 | L33: 0 | M33: 0 | N33: 0 | O33: 0 | P33: 0 | R33: =SUM(J33:J33) -> 504489.82 | S33: =SUM(L33:P33) -> 0 | U33: =R33+S33 -> 504489.82 | W33: =U33*0.05 -> 25224.491 | X33: =U33*0.04 -> 20179.593 | Y33: =U33*0.01 -> 5044.8982 | Z33: =U33*0.03 -> 15134.695 | AA33: =U33*0.005 -> 2522.4491 | AC33: =R33+SUM(W33:AA33) -> 572595.95 | AD33: 0 | AE33: =SUM(AC33:AD33) -> 572595.95 | AG33: =AE33*0.268 -> 153455.71 | AI33: =AC33+AC33*0.268 -> 726051.66 | AJ33: =AD33+AD33*0.268 -> 0 | AL33: =SUM(AI33:AJ33) -> 726051.66 | AN33: =AL33/G33 -> 48403.444
A34: 1 | B34: =MID('07_Floresta'!$B$16,16,6) -> A4S5R3 | C34: =RIGHT(B34,2) -> R3 | D34: =MID('07_Floresta'!$A$3,51,7) -> Malhado | E34: =MID('07_Floresta'!$A$3,34,8) -> Floresta | G34: 63 | J34: ='07_Floresta'!K16 -> 2693265.8 | L34: 0 | M34: 0 | N34: 0 | O34: 0 | P34: 0 | R34: =SUM(J34:J34) -> 2693265.8 | S34: =SUM(L34:P34) -> 0 | U34: =R34+S34 -> 2693265.8 | W34: =U34*0.05 -> 134663.29 | X34: =U34*0.04 -> 107730.63 | Y34: =U34*0.01 -> 26932.658 | Z34: =U34*0.03 -> 80797.974 | AA34: =U34*0.005 -> 13466.329 | AC34: =R34+SUM(W34:AA34) -> 3056856.7 | AD34: 0 | AE34: =SUM(AC34:AD34) -> 3056856.7 | AG34: =AE34*0.268 -> 819237.59 | AI34: =AC34+AC34*0.268 -> 3876094.3 | AJ34: =AD34+AD34*0.268 -> 0 | AL34: =SUM(AI34:AJ34) -> 3876094.3 | AN34: =AL34/G34 -> 61525.306
A35: 1 | B35: =MID('07_Floresta'!$B$47,16,6) -> A4S6R4 | C35: =RIGHT(B35,2) -> R4 | D35: =MID('07_Floresta'!$A$3,51,7) -> Malhado | E35: =MID('07_Floresta'!$A$3,34,8) -> Floresta | G35: 124 | J35: ='07_Floresta'!K47 -> 757999.24 | L35: 0 | M35: 0 | N35: 0 | O35: 0 | P35: 0 | R35: =SUM(J35:J35) -> 757999.24 | S35: =SUM(L35:P35) -> 0 | U35: =R35+S35 -> 757999.24 | W35: =U35*0.05 -> 37899.962 | X35: =U35*0.04 -> 30319.97 | Y35: =U35*0.01 -> 7579.9924 | Z35: =U35*0.03 -> 22739.977 | AA35: =U35*0.005 -> 3789.9962 | AC35: 0 | AD35: =S35+SUM(W35:AA35) -> 102329.9 | AE35: =SUM(AC35:AD35) -> 102329.9 | AG35: =AE35*0.268 -> 27424.413 | AI35: =AC35+AC35*0.268 -> 0 | AJ35: =AD35+AD35*0.268 -> 129754.31 | AL35: =SUM(AI35:AJ35) -> 129754.31 | AN35: =AL35/G35 -> 1046.4057
H36: =SUM(G33:G35) -> 202 | J36: 0 | L36: 0 | M36: 0 | N36: 0 | O36: 0 | P36: 0 | R36: =SUM(J36:J36) -> 0 | S36: =SUM(L36:P36) -> 0 | U36: =R36+S36 -> 0 | W36: =U36*0.05 -> 0 | X36: =U36*0.04 -> 0 | Y36: =U36*0.01 -> 0 | Z36: =U36*0.03 -> 0 | AA36: =U36*0.005 -> 0 | AC36: 0 | AD36: =S36+SUM(W36:AA36) -> 0 | AE36: =SUM(AC36:AD36) -> 0 | AG36: =AE36*0.268 -> 0 | AI36: =AC36+AC36*0.268 -> 0 | AJ36: =AD36+AD36*0.268 -> 0 | AL36: =SUM(AI36:AJ36) -> 0 | AN36: =AL36/H36 -> 0
A38: 1 | B38: =MID('08_Coqueiro'!$B$5,16,6) -> A2S1R3 | C38: =RIGHT(B38,2) -> R3 | D38: =MID('08_Coqueiro'!$A$3,51,7) -> Malhado | E38: =MID('08_Coqueiro'!$A$3,34,8) -> Coqueiro | G38: 25 | J38: ='08_Coqueiro'!K5 -> 995770.49 | L38: 0 | M38: 0 | N38: 0 | O38: 0 | P38: 0 | R38: =SUM(J38:J38) -> 995770.49 | S38: =SUM(L38:P38) -> 0 | U38: =R38+S38 -> 995770.49 | W38: =U38*0.05 -> 49788.524 | X38: =U38*0.04 -> 39830.82 | Y38: =U38*0.01 -> 9957.7049 | Z38: =U38*0.03 -> 29873.115 | AA38: =U38*0.005 -> 4978.8525 | AC38: =R38+SUM(W38:AA38) -> 1130199.5 | AD38: 0 | AE38: =SUM(AC38:AD38) -> 1130199.5 | AG38: =AE38*0.268 -> 302893.47 | AI38: =AC38+AC38*0.268 -> 1433093 | AJ38: =AD38+AD38*0.268 -> 0 | AL38: =SUM(AI38:AJ38) -> 1433093 | AN38: =AL38/G38 -> 57323.719
A39: 1 | B39: =MID('08_Coqueiro'!$B$41,16,6) -> A3S2R3 | C39: =RIGHT(B39,2) -> R3 | D39: =MID('08_Coqueiro'!$A$3,51,7) -> Malhado | E39: =MID('08_Coqueiro'!$A$3,34,8) -> Coqueiro | G39: 98 | J39: ='08_Coqueiro'!K41 -> 3858154.4 | L39: 0 | M39: 0 | N39: 0 | O39: 0 | P39: 0 | R39: =SUM(J39:J39) -> 3858154.4 | S39: =SUM(L39:P39) -> 0 | U39: =R39+S39 -> 3858154.4 | W39: =U39*0.05 -> 192907.72 | X39: =U39*0.04 -> 154326.18 | Y39: =U39*0.01 -> 38581.544 | Z39: =U39*0.03 -> 115744.63 | AA39: =U39*0.005 -> 19290.772 | AC39: =R39+SUM(W39:AA39) -> 4379005.3 | AD39: 0 | AE39: =SUM(AC39:AD39) -> 4379005.3 | AG39: =AE39*0.268 -> 1173573.4 | AI39: =AC39+AC39*0.268 -> 5552578.7 | AJ39: =AD39+AD39*0.268 -> 0 | AL39: =SUM(AI39:AJ39) -> 5552578.7 | AN39: =AL39/G39 -> 56658.966
A40: 1 | B40: =MID('08_Coqueiro'!$B$57,16,6) -> A5S1R3 | C40: =RIGHT(B40,2) -> R3 | D40: =MID('08_Coqueiro'!$A$3,51,7) -> Malhado | E40: =MID('08_Coqueiro'!$A$3,34,8) -> Coqueiro | G40: 9 | J40: ='08_Coqueiro'!K57 -> 34360.77 | L40: 0 | M40: 0 | N40: 0 | O40: 0 | P40: 0 | R40: =SUM(J40:J40) -> 34360.77 | S40: =SUM(L40:P40) -> 0 | U40: =R40+S40 -> 34360.77 | W40: =U40*0.05 -> 1718.0385 | X40: =U40*0.04 -> 1374.4308 | Y40: =U40*0.01 -> 343.6077 | Z40: =U40*0.03 -> 1030.8231 | AA40: =U40*0.005 -> 171.80385 | AC40: =R40+SUM(W40:AA40) -> 38999.474 | AD40: 0 | AE40: =SUM(AC40:AD40) -> 38999.474 | AG40: =AE40*0.268 -> 10451.859 | AI40: =AC40+AC40*0.268 -> 49451.333 | AJ40: =AD40+AD40*0.268 -> 0 | AL40: =SUM(AI40:AJ40) -> 49451.333 | AN40: =AL40/G40 -> 5494.5926
A41: 1 | B41: =MID('08_Coqueiro'!$B$73,16,6) -> A6S1R4 | C41: =RIGHT(B41,2) -> R4 | D41: =MID('08_Coqueiro'!$A$3,51,7) -> Malhado | E41: =MID('08_Coqueiro'!$A$3,34,8) -> Coqueiro | G41: 10 | J41: ='08_Coqueiro'!K73 -> 453427.49 | L41: 0 | M41: 0 | N41: 0 | O41: 0 | P41: 0 | R41: =SUM(J41:J41) -> 453427.49 | S41: =SUM(L41:P41) -> 0 | U41: =R41+S41 -> 453427.49 | W41: =U41*0.05 -> 22671.375 | X41: =U41*0.04 -> 18137.1 | Y41: =U41*0.01 -> 4534.2749 | Z41: =U41*0.03 -> 13602.825 | AA41: =U41*0.005 -> 2267.1375 | AC41: =R41+SUM(W41:AA41) -> 514640.2 | AD41: 0 | AE41: =SUM(AC41:AD41) -> 514640.2 | AG41: =AE41*0.268 -> 137923.57 | AI41: =AC41+AC41*0.268 -> 652563.78 | AJ41: =AD41+AD41*0.268 -> 0 | AL41: =SUM(AI41:AJ41) -> 652563.78 | AN41: =AL41/G41 -> 65256.378
H42: =SUM(G38:G41) -> 142 | J42: 0 | L42: ='08_Coqueiro'!H94 -> 139725.19 | M42: ='08_Coqueiro'!H100 -> 487554.32 | N42: ='08_Coqueiro'!H106 -> 4882545.1 | O42: ='08_Coqueiro'!H126 -> 224274.18 | P42: ='08_Coqueiro'!H129 -> 72436 | R42: =SUM(J42:J42) -> 0 | S42: =SUM(L42:P42) -> 5806534.8 | U42: =R42+S42 -> 5806534.8 | W42: =U42*0.05 -> 290326.74 | X42: =U42*0.04 -> 232261.39 | Y42: =U42*0.01 -> 58065.348 | Z42: =U42*0.03 -> 174196.04 | AA42: =U42*0.005 -> 29032.674 | AC42: 0 | AD42: =S42+SUM(W42:AA42) -> 6590417 | AE42: =SUM(AC42:AD42) -> 6590417 | AG42: =AE42*0.268 -> 1766231.8 | AI42: =AC42+AC42*0.268 -> 0 | AJ42: =AD42+AD42*0.268 -> 8356648.8 | AL42: =SUM(AI42:AJ42) -> 8356648.8 | AN42: =AL42/H42 -> 58849.639
A44: 1 | B44: =MID('09_Legião'!$B$5,16,6) -> A4S3R3 | C44: =RIGHT(B44,2) -> R3 | D44: =MID('09_Legião'!$A$3,49,7) -> Malhado | E44: =MID('09_Legião'!$A$3,34,6) -> Legião | G44: 13 | J44: ='09_Legião'!K5 -> 74337.03 | L44: 0 | M44: 0 | N44: 0 | O44: 0 | P44: 0 | R44: =SUM(J44:J44) -> 74337.03 | S44: =SUM(L44:P44) -> 0 | U44: =R44+S44 -> 74337.03 | W44: =U44*0.05 -> 3716.8515 | X44: =U44*0.04 -> 2973.4812 | Y44: =U44*0.01 -> 743.3703 | Z44: =U44*0.03 -> 2230.1109 | AA44: =U44*0.005 -> 371.68515 | AC44: =R44+SUM(W44:AA44) -> 84372.529 | AD44: 0 | AE44: =SUM(AC44:AD44) -> 84372.529 | AG44: =AE44*0.268 -> 22611.838 | AI44: =AC44+AC44*0.268 -> 106984.37 | AJ44: =AD44+AD44*0.268 -> 0 | AL44: =SUM(AI44:AJ44) -> 106984.37 | AN44: =AL44/G44 -> 8229.5667
A45: 1 | B45: =MID('09_Legião'!$B$32,16,6) -> A4S5R3 | C45: =RIGHT(B45,2) -> R3 | D45: =MID('09_Legião'!$A$3,49,7) -> Malhado | E45: =MID('09_Legião'!$A$3,34,6) -> Legião | G45: 22 | J45: ='09_Legião'!K32 -> 767384.04 | L45: 0 | M45: 0 | N45: 0 | O45: 0 | P45: 0 | R45: =SUM(J45:J45) -> 767384.04 | S45: =SUM(L45:P45) -> 0 | U45: =R45+S45 -> 767384.04 | W45: =U45*0.05 -> 38369.202 | X45: =U45*0.04 -> 30695.362 | Y45: =U45*0.01 -> 7673.8404 | Z45: =U45*0.03 -> 23021.521 | AA45: =U45*0.005 -> 3836.9202 | AC45: =R45+SUM(W45:AA45) -> 870980.89 | AD45: 0 | AE45: =SUM(AC45:AD45) -> 870980.89 | AG45: =AE45*0.268 -> 233422.88 | AI45: =AC45+AC45*0.268 -> 1104403.8 | AJ45: =AD45+AD45*0.268 -> 0 | AL45: =SUM(AI45:AJ45) -> 1104403.8 | AN45: =AL45/G45 -> 50200.171
A46: 1 | B46: =MID('09_Legião'!$B$52,16,6) -> A4S7R3 | C46: =RIGHT(B46,2) -> R3 | D46: =MID('09_Legião'!$A$3,49,7) -> Malhado | E46: =MID('09_Legião'!$A$3,34,6) -> Legião | G46: 38 | J46: ='09_Legião'!K52 -> 1032007.3 | L46: 0 | M46: 0 | N46: 0 | O46: 0 | P46: 0 | R46: =SUM(J46:J46) -> 1032007.3 | S46: =SUM(L46:P46) -> 0 | U46: =R46+S46 -> 1032007.3 | W46: =U46*0.05 -> 51600.366 | X46: =U46*0.04 -> 41280.293 | Y46: =U46*0.01 -> 10320.073 | Z46: =U46*0.03 -> 30960.22 | AA46: =U46*0.005 -> 5160.0366 | AC46: =R46+SUM(W46:AA46) -> 1171328.3 | AD46: 0 | AE46: =SUM(AC46:AD46) -> 1171328.3 | AG46: =AE46*0.268 -> 313915.99 | AI46: =AC46+AC46*0.268 -> 1485244.3 | AJ46: =AD46+AD46*0.268 -> 0 | AL46: =SUM(AI46:AJ46) -> 1485244.3 | AN46: =AL46/G46 -> 39085.376
H47: =SUM(G44:G46) -> 73 | J47: 0 | L47: 0 | M47: 0 | N47: 0 | O47: 0 | P47: 0 | R47: =SUM(J47:J47) -> 0 | S47: =SUM(L47:P47) -> 0 | U47: =R47+S47 -> 0 | W47: =U47*0.05 -> 0 | X47: =U47*0.04 -> 0 | Y47: =U47*0.01 -> 0 | Z47: =U47*0.03 -> 0 | AA47: =U47*0.005 -> 0 | AC47: 0 | AD47: =S47+SUM(W47:AA47) -> 0 | AE47: =SUM(AC47:AD47) -> 0 | AG47: =AE47*0.268 -> 0 | AI47: =AC47+AC47*0.268 -> 0 | AJ47: =AD47+AD47*0.268 -> 0 | AL47: =SUM(AI47:AJ47) -> 0 | AN47: =AL47/H47 -> 0
A49: 1 | B49: =MID('10_Amparo'!$B$5,16,6) -> A2S1R3 | C49: =RIGHT(B49,2) -> R3 | D49: =MID('10_Amparo'!$A$3,49,7) -> Malhado | E49: =MID('10_Amparo'!$A$3,34,6) -> Amparo | G49: 35 | J49: ='10_Amparo'!K5 -> 901859.2 | L49: 0 | M49: 0 | N49: 0 | O49: 0 | P49: 0 | R49: =SUM(J49:J49) -> 901859.2 | S49: =SUM(L49:P49) -> 0 | U49: =R49+S49 -> 901859.2 | W49: =U49*0.05 -> 45092.96 | X49: =U49*0.04 -> 36074.368 | Y49: =U49*0.01 -> 9018.592 | Z49: =U49*0.03 -> 27055.776 | AA49: =U49*0.005 -> 4509.296 | AC49: =R49+SUM(W49:AA49) -> 1023610.2 | AD49: 0 | AE49: =SUM(AC49:AD49) -> 1023610.2 | AG49: =AE49*0.268 -> 274327.53 | AI49: =AC49+AC49*0.268 -> 1297937.7 | AJ49: =AD49+AD49*0.268 -> 0 | AL49: =SUM(AI49:AJ49) -> 1297937.7 | AN49: =AL49/G49 -> 37083.935
...

Sheet 01_Carvalho
C1: PMRR DE ILHÉUS
C3: Empreendimento: 000058 - Alto do Carvalho (Bairro Esperança) | I3: VALOR TOTAL
A4: CODIGO_ALTO | B4: CODIGO_ORSE | C4: ITEM | D4: DESCRIÇÃO DO ITEM | E4: UNID | F4: QUANT | G4: PREÇO UNIT | I4: Valor Parcial | K4: Parcial (%) | M4: Soma | N4: (%)
A5: ESPCAR_A1S1R3 | C5: 1 | D5: Setor de Risco A1S1R3 (Contenções e Demolições) | M5: =SUM(J6:J34) -> 386572.95 | N5: =M5/$I$177 -> 0.20285395
A6: ESPCAR_A1S1R3 | C6: 01.01 | D6: SERVIÇOS PRELIMINARES | J6: =I7 -> 9766.77 | K6: =J6/$M$5 -> 0.025265011
A7: ESPCAR_A1S1R3 | C7: 01.01.001 | D7: LIMPEZA DE TERRENO | I7: =SUM(I8:I11) -> 9766.77 | K7: =I7/$M$5 -> 0.025265011
A8: ESPCAR_A1S1R3 | B8: 0003/ ORSE | C8: 01.01.001.001 | D8: Limpeza manual de terreno com vegetação rasteira, incluindo roçagem e queima | E8: m2 | F8: 356 | G8: 4.38 | I8: 1559.28 | K8: =I8/$M$5 -> 0.0040335983
A9: ESPCAR_A1S1R3 | B9: 5029/ ORSE | C9: 01.01.001.002 | D9: Destocamento de árvores de porte médio e raízes profundas, sem auxílio mecânico | E9: un | F9: 8.9 | G9: 217.25 | I9: 1933.53 | K9: =I9/$M$5 -> 0.0050017209
A10: ESPCAR_A1S1R3 | B10: 0026/ ORSE | C10: 01.01.001.003 | D10: Coleta e carga manuais de entulho | E10: m3 | F10: 106.8 | G10: 17.54 | I10: 1873.27 | K10: =I10/$M$5 -> 0.0048458383
A11: ESPCAR_A1S1R3 | B11: 97917/ SINAPI | C11: 01.01.001.004 | D11: Transporte com caminhão basculante de 6 m³, em via urbana em revestimento primário (unidade: txkm). af_07/2020 | E11: txkm | F11: 2146.68 | G11: 2.05 | I11: 4400.69 | K11: =I11/$M$5 -> 0.011383854
A12: ESPCAR_A1S1R3 | C12: 01.02 | D12: ESTRUTURAS DE CONTENÇÃO | J12: =I13+I15 -> 360679.14 | K12: =J12/$M$5 -> 0.93301702
A13: ESPCAR_A1S1R3 | C13: 01.02.001 | D13: SOLO GRAMPEADO | I13: =I14 -> 221132.96 | K13: =I13/$M$5 -> 0.57203423
A14: ESPCAR_A1S1R3 | B14: 13481/ ORSE | C14: 01.02.001.001 | D14: Solo Grampeado para controlede erosão com malha hexagonal de dupla torção, revestimento em PVC e com resistência de puncionamento de 105 KN e resistência à tração de 89 KN/m. Associada a geomanta tridimensional verde. | E14: m2 | F14: 293 | G14: 754.72 | I14: 221132.96 | K14: =I14/$M$5 -> 0.57203423
A15: ESPCAR_A1S1R3 | C15: 01.02.002 | D15: MURO DE ARRIMO | I15: =SUM(I16:I29) -> 139546.18 | K15: =I15/$M$5 -> 0.36098278
A16: ESPCAR_A1S1R3 | B16: 03672/ SINAPI | C16: 01.02.002.001 | D16: Concretagem de pilares, fck = 25 mpa, com uso de bomba - lançamento, adensamento e acabamento. af_02/2022_ps | E16: m3 | F16: 25.2 | G16: 641.26 | I16: 16159.75 | K16: =I16/$M$5 -> 0.041802589
A17: ESPCAR_A1S1R3 | B17: 02923/ SINAPI | C17: 01.02.002.002 | D17: Armação de cinta de alvenaria estrutural; diâmetro de 16,0 mm. af_09/2021 | E17: kg | F17: 630 | G17: 8.64 | I17: 5443.2 | K17: =I17/$M$5 -> 0.014080654
A18: ESPCAR_A1S1R3 | B18: 02922/ SINAPI | C18: 01.02.002.003 | D18: Armação de verga e contraverga de alvenaria estrutural; diâmetro de 16,0 mm. af_09/2021 | E18: kg | F18: 1134 | G18: 9.66 | I18: 10954.44 | K18: =I18/$M$5 -> 0.028337316
A19: ESPCAR_A1S1R3 | B19: 02921/ SINAPI | C19: 01.02.002.004 | D19: Armação vertical de alvenaria estrutural; diâmetro de 16,0 mm. af_09/2021 | E19: kg | F19: 1134 | G19: 8.84 | I19: 10024.56 | K19: =I19/$M$5 -> 0.025931871
A20: ESPCAR_A1S1R3 | B20: 93382/ SINAPI | C20: 01.02.002.005 | D20: Reaterro manual de valas, com compactador de solos de percussão. af_08/2023 | E20: m3 | F20: 50.4 | G20: 25.13 | I20: 1266.55 | K20: =I20/$M$5 -> 0.0032763544
A21: ESPCAR_A1S1R3 | B21: 89994/ SINAPI | C21: 01.02.002.006 | D21: Grauteamento de cinta intermediária ou de contraverga em alvenaria estrutural. af_09/2021 | E21: m3 | F21: 1.26 | G21: 900.01 | I21: 1134.01 | K21: =I21/$M$5 -> 0.0029334955
A22: ESPCAR_A1S1R3 | B22: 89995/ SINAPI | C22: 01.02.002.007 | D22: Grauteamento de cinta superior ou de verga em alvenaria estrutural. af_09/2021 | E22: m3 | F22: 1.26 | G22: 1002.12 | I22: 1262.67 | K22: =I22/$M$5 -> 0.0032663175
A23: ESPCAR_A1S1R3 | B23: 89993/ SINAPI | C23: 01.02.002.008 | D23: Grauteamento vertical em alvenaria estrutural. af_09/2021 | E23: m3 | F23: 31.5 | G23: 1037.21 | I23: 32672.12 | K23: =I23/$M$5 -> 0.084517347
A24: ESPCAR_A1S1R3 | B24: 9377/ ORSE | C24: 01.02.002.009 | D24: Tubo pvc rigido soldavel, serie reforçada, p/esgoto e aguas pluviais, d= 100mm | E24: m | F24: 31.5 | G24: 45.3 | I24: 1426.95 | K24: =I24/$M$5 -> 0.0036912826
A25: ESPCAR_A1S1R3 | B25: 89472/ SINAPI | C25: 01.02.002.010 | D25: Alvenaria de blocos de concreto estrutural 14x19x39 cm (espessura 14 cm), fbk = 14 mpa, utilizando colher de pedreiro. af_10/2022 | E25: m2 | F25: 63 | G25: 106.17 | I25: 6688.71 | K25: =I25/$M$5 -> 0.017302582
A26: ESPCAR_A1S1R3 | B26: 96525/ SINAPI | C26: 01.02.002.011 | D26: Escavação mecanizada para viga baldrame ou sapata corrida com mini-escavadeira (incluindo escavação para colocação de fôrmas). af_01/2024 | E26: m3 | F26: 50.4 | G26: 56.85 | I26: 2865.24 | K26: =I26/$M$5 -> 0.0074118999
A27: ESPCAR_A1S1R3 | B27: 04927/ SINAPI | C27: 01.02.002.012 | D27: Fabricação, montagem e desmontagem de fôrma para sapata corrida, em madeira serrada, e=25 mm, 4 utilizações. af_01/2024 | E27: m2 | F27: 50.4 | G27: 76.84 | I27: 3872.74 | K27: =I27/$M$5 -> 0.010018135
... A29: ESPCAR_A1S1R3 | B29: 04924/SINAPI | C29: 01.02.002.014 | D29: Concretagem de sapata corrida, fck 30 mpa, com uso de bomba - lançamento, adensamento e acabamento. af_01/2024 | E29: m3 | F29: 50.4 | G29: 734.02 | I29: 36994.61 | K29: =I29/$M$5 -> 0.09569891
A30: ESPCAR_A1S1R3 | B30: -- | C30: 01.03 | D30: DRENAGEM DAS ESTRUTURAS DE CONTENÇÃO | J30: =I31+I33 -> 16127.04 | K30: =J30/$M$5 -> 0.041717973
A31: ESPCAR_A1S1R3 | B31: -- | C31: 01.03.001 | D31: CANALETA | I31: =I32 -> 2444 | K31: =I31/$M$5 -> 0.006322222
A32: ESPCAR_A1S1R3 | B32: 02989/ SINAPI | C32: 01.03.001.001 | D32: Canaleta meia cana pré-moldada de concreto (d = 20 cm) - fornecimento e instalação. af_08/2021 | E32: m | F32: 80 | G32: 30.55 | I32: 2444 | K32: =I32/$M$5 -> 0.006322222
A33: ESPCAR_A1S1R3 | B33: -- | C33: 01.03.002 | D33: ESCADA HIDRÁULICA | I33: =I34 -> 13683.04 | K33: =I33/$M$5 -> 0.035395751
A34: ESPCAR_A1S1R3 | B34: 03925/ SINAPI | C34: 01.03.002.001 | D34: Escada hidráulica, largura até 1m, tipo descida d'água de corte ou aterro em degraus (dcd 02, 04 e dad 02), em concreto usinado, fck = 20 mpa, lançado com bomba, incluindo armação, materiais e fôrmas (3 utilizações). af_08/2022 | E34: m3 | F34: 8 | G34: 1710.38 | I34: 13683.04 | K34: =I34/$M$5 -> 0.035395751
A36: ESPCAR_A1S2R4 | B36: -- | C36: 2 | D36: Setor de Risco A1S2R4 (Contenções e Demolições) | M36: =SUM(J37:J65) -> 743321.27 | N36: =M36/$I$177 -> 0.39005743
A37: ESPCAR_A1S2R4 | B37: -- | C37: 02.01 | D37: SERVIÇOS PRELIMINARES | J37: =I38 -> 25048.97 | K37: =J37/$M$36 -> 0.033698713
A38: ESPCAR_A1S2R4 | B38: -- | C38: 02.01.001 | D38: LIMPEZA DE TERRENO | I38: =SUM(I39:I42) -> 25048.97 | K38: =I38/$M$36 -> 0.033698713
A39: ESPCAR_A1S2R4 | B39: 0003/ ORSE | C39: 02.01.001.001 | D39: Limpeza manual de terreno com vegetação rasteira, incluindo roçagem e queima | E39: m2 | F39: 913 | G39: 4.38 | I39: 3998.94 | K39: =I39/$M$36 -> 0.0053798272
A40: ESPCAR_A1S2R4 | B40: 5029/ ORSE | C40: 02.01.001.002 | D40: Destocamento de árvores de porte médio e raízes profundas, sem auxílio mecânico | E40: un | F40: 22.83 | G40: 217.25 | I40: 4958.73 | K40: =I40/$M$36 -> 0.0066710455
A41: ESPCAR_A1S2R4 | B41: 0026/ ORSE | C41: 02.01.001.003 | D41: Coleta e carga manuais de entulho | E41: m3 | F41: 273.9 | G41: 17.54 | I41: 4804.21 | K41: =I41/$M$36 -> 0.0064631677
A42: ESPCAR_A1S2R4 | B42: 97917/ SINAPI | C42: 02.01.001.004 | D42: Transporte com caminhão basculante de 6 m³, em via urbana em revestimento primário (unidade: txkm). af_07/2020 | E42: txkm | F42: 5505.9 | G42: 2.05 | I42: 11287.09 | K42: =I42/$M$36 -> 0.015184672
A43: ESPCAR_A1S2R4 | B43: -- | C43: 02.02 | D43: ESTRUTURAS DE CONTENÇÃO | J43: =I44+I46 -> 712670.02 | K43: =J43/$M$36 -> 0.95876447
...

Sheet 02_Esperança
A1: PMRR DE ILHÉUS
A3: Empreendimento: 000055 - Alto da Esperança (Bairro Esperança) | G3: VALOR TOTAL
A4: ITEM | B4: DESCRIÇÃO DO ITEM | C4: UNID | D4: QUANT | E4: PREÇO UNIT | G4: Valor Parcial | I4: Parcial (%) | K4: Soma | L4: (%)
A5: 1 | B5: Setor de Risco A1S2R4 (Contenções e Demolições) | K5: =SUM(H5:H34) -> 99348.32 | L5: =K5/$G$211 -> 0.017856259
A6: 01.01 | B6: SERVIÇOS PRELIMINARES | H6: =G7 -> 2167.35 | I6: =H6/$K$5 -> 0.021815668
A7: 01.01.001 | B7: LIMPEZA DE TERRENO | G7: =SUM(G8:G11) -> 2167.35 | I7: =G7/$K$5 -> 0.021815668
A8: 01.01.001.001 | B8: Limpeza manual de terreno com vegetação rasteira, incluindo roçagem e queima | C8: m2 | D8: 79 | E8: 4.38 | G8: 346.02 | I8: =G8/$K$5 -> 0.0034828973
A9: 01.01.001.002 | B9: Destocamento de árvores de porte médio e raízes profundas, sem auxílio mecânico | C9: un | D9: 1.98 | E9: 217.25 | G9: 429.07 | I9: =G9/$K$5 -> 0.004318845
A10: 01.01.001.003 | B10: Coleta e carga manuais de entulho | C10: m3 | D10: 23.7 | E10: 17.54 | G10: 415.7 | I10: =G10/$K$5 -> 0.004184268
A11: 01.01.001.004 | B11: Transporte com caminhão basculante de 6 m³, em via urbana em revestimento primário (unidade: txkm). af_07/2020 | C11: txkm | D11: 476.37 | E11: 2.05 | G11: 976.56 | I11: =G11/$K$5 -> 0.0098296579
A12: 01.02 | B12: ESTRUTURAS DE CONTENÇÃO | H12: =G13+G15 -> 94670.05 | I12: =H12/$K$5 -> 0.95291043
A13: 01.02.001 | B13: SOLO GRAMPEADO | G13: =G14 -> 41509.6 | I13: =G13/$K$5 -> 0.41781884
A14: 01.02.001.001 | B14: Solo Grampeado para controlede erosão com malha hexagonal de dupla torção, revestimento em PVC e com resistência de puncionamento de 105 KN e resistência à tração de 89 KN/m. Associada a geomanta tridimensional verde. | C14: m2 | D14: 55 | E14: 754.72 | G14: 41509.6 | I14: =G14/$K$5 -> 0.41781884
A15: 01.02.002 | B15: MURO DE ARRIMO | G15: =SUM(G16:G29) -> 53160.45 | I15: =G15/$K$5 -> 0.53509158
A16: 01.02.002.001 | B16: Concretagem de pilares, fck = 25 mpa, com uso de bomba - lançamento, adensamento e acabamento. af_02/2022_ps | C16: m3 | D16: 9.6 | E16: 641.26 | G16: 6156.1 | I16: =G16/$K$5 -> 0.061964812
A17: 01.02.002.002 | B17: Armação de cinta de alvenaria estrutural; diâmetro de 16,0 mm. af_09/2021 | C17: kg | D17: 240 | E17: 8.64 | G17: 2073.6 | I17: =G17/$K$5 -> 0.020872019
A18: 01.02.002.003 | B18: Armação de verga e contraverga de alvenaria estrutural; diâmetro de 16,0 mm. af_09/2021 | C18: kg | D18: 432 | E18: 9.66 | G18: 4173.12 | I18: =G18/$K$5 -> 0.042004938
A19: 01.02.002.004 | B19: Armação vertical de alvenaria estrutural; diâmetro de 16,0 mm. af_09/2021 | C19: kg | D19: 432 | E19: 8.84 | G19: 3818.88 | I19: =G19/$K$5 -> 0.038439301
A20: 01.02.002.005 | B20: Reaterro manual de valas, com compactador de solos de percussão. af_08/2023 | C20: m3 | D20: 19.2 | E20: 25.13 | G20: 482.5 | I20: =G20/$K$5 -> 0.0048566498
A21: 01.02.002.006 | B21: Grauteamento de cinta intermediária ou de contraverga em alvenaria estrutural. af_09/2021 | C21: m3 | D21: 0.48 | E21: 900.01 | G21: 432 | I21: =G21/$K$5 -> 0.0043483372
A22: 01.02.002.007 | B22: Grauteamento de cinta superior ou de verga em alvenaria estrutural. af_09/2021 | C22: m3 | D22: 0.48 | E22: 1002.12 | G22: 481.02 | I22: =G22/$K$5 -> 0.0048417527
A23: 01.02.002.008 | B23: Grauteamento vertical em alvenaria estrutural. af_09/2021 | C23: m3 | D23: 12 | E23: 1037.21 | G23: 12446.52 | I23: =G23/$K$5 -> 0.12528164
A24: 01.02.002.009 | B24: Tubo pvc rigido soldavel, serie reforçada, p/esgoto e aguas pluviais, d= 100mm | C24: m | D24: 12 | E24: 45.3 | G24: 543.6 | I24: =G24/$K$5 -> 0.0054716577
A25: 01.02.002.010 | B25: Alvenaria de blocos de concreto estrutural 14x19x39 cm (espessura 14 cm), fbk = 14 mpa, utilizando colher de pedreiro. af_10/2022 | C25: m2 | D25: 24 | E25: 106.17 | G25: 2548.08 | I25: =G25/$K$5 -> 0.025647943
A26: 01.02.002.011 | B26: Escavação mecanizada para viga baldrame ou sapata corrida com mini-escavadeira (incluindo escavação para colocação de fôrmas). af_01/2024 | C26: m3 | D26: 19.2 | E26: 56.85 | G26: 1091.52 | I26: =G26/$K$5 -> 0.010986799
A27: 01.02.002.012 | B27: Fabricação, montagem e desmontagem de fôrma para sapata corrida, em madeira serrada, e=25 mm, 4 utilizações. af_01/2024 | C27: m2 | D27: 19.2 | E27: 76.84 | G27: 1475.33 | I27: =G27/$K$5 -> 0.014850075
... A29: 01.02.002.014 | B29: Concretagem de sapata corrida, fck 30 mpa, com uso de bomba - lançamento, adensamento e acabamento. af_01/2024 | C29: m3 | D29: 19.2 | E29: 734.02 | G29: 14093.18 | I29: =G29/$K$5 -> 0.14185625
A30: 01.03 | B30: DRENAGEM DAS ESTRUTURAS DE CONTENÇÃO | H30: =G31+G33 -> 2510.92 | I30: =H30/$K$5 -> 0.025273905
A31: 01.03.001 | B31: CANALETA | G31: =G32 -> 1313.65 | I31: =G31/$K$5 -> 0.013222669
A32: 01.03.001.001 | B32: Canaleta meia cana pré-moldada de concreto (d = 20 cm) - fornecimento e instalação. af_08/2021 | C32: m | D32: 43 | E32: 30.55 | G32: 1313.65 | I32: =G32/$K$5 -> 0.013222669
A33: 01.03.002 | B33: ESCADA HIDRÁULICA | G33: =G34 -> 1197.27 | I33: =G33/$K$5 -> 0.012051235
A34: 01.03.002.001 | B34: Escada hidráulica, largura até 1m, tipo descida d'água de corte ou aterro em degraus (dcd 02, 04 e dad 02), em concreto usinado, fck = 20 mpa, lançado com bomba, incluindo armação, materiais e fôrmas (3 utilizações). af_08/2022 | C34: m3 | D34: 0.7 | E34: 1710.38 | G34: 1197.27 | I34: =G34/$K$5 -> 0.012051235
A36: 2 | B36: Setor de Risco A1S3R3 (Contenções e Demolições) | K36: =SUM(H36:H72) -> 1422949.4 | L36: =K36/$G$211 -> 0.25575221
A37: 02.01 | B37: SERVIÇOS PRELIMINARES | H37: =G38+G43 -> 47382.07 | I37: =H37/$K$36 -> 0.033298492
A38: 02.01.001 | B38: LIMPEZA DE TERRENO | G38: =SUM(G39:G42) -> 43127.42 | I38: =G38/$K$36 -> 0.03030847
A39: 02.01.001.001 | B39: Limpeza manual de terreno com vegetação rasteira, incluindo roçagem e queima | C39: m2 | D39: 1572 | E39: 4.38 | G39: 6885.36 | I39: =G39/$K$36 -> 0.0048387947
A40: 02.01.001.002 | B40: Destocamento de árvores de porte médio e raízes profundas, sem auxílio mecânico | C40: un | D40: 39.3 | E40: 217.25 | G40: 8537.92 | I40: =G40/$K$36 -> 0.0060001571
A41: 02.01.001.003 | B41: Coleta e carga manuais de entulho | C41: m3 | D41: 471.6 | E41: 17.54 | G41: 8271.86 | I41: =G41/$K$36 -> 0.0058131793
A42: 02.01.001.004 | B42: Transporte com caminhão basculante de 6 m³, em via urbana em revestimento primário (unidade: txkm). af_07/2020 | C42: txkm | D42: 9479.16 | E42: 2.05 | G42: 19432.28 | I42: =G42/$K$36 -> 0.013656339
A43: 02.01.002 | B43: DEMOLIÇÃO DE EDIFICAÇÕES | G43: =SUM(G44:G49) -> 4254.65 | I43: =G43/$K$36 -> 0.002990022
...

Sheet 03_Aureliano
A1: PMRR DE ILHÉUS
A3: Empreendimento: 000071 - Alto Aureliano (Bairro Esperança) | G3: VALOR TOTAL
A4: ITEM | B4: DESCRIÇÃO DO ITEM | C4: UNID | D4: QUANT | E4: PREÇO UNIT | G4: Valor Parcial | I4: Parcial (%) | K4: Soma | L4: (%)
A5: 1 | B5: Setor de Risco A1S1R4 (Contenções e Demolições) | K5: =SUM(H5:H61) -> 3705680.7 | L5: =K5/$G$149 -> 0.70833438
A6: 01.01 | B6: SERVIÇOS PRELIMINARES | H6: =G7+G12 -> 77577.85 | I6: =H6/$K$5 -> 0.020934845
A7: 01.01.001 | B7: LIMPEZA DE TERRENO | G7: =SUM(G8:G11) -> 70809.09 | I7: =G7/$K$5 -> 0.019108254
A8: 01.01.001.001 | B8: Limpeza manual de terreno com vegetação rasteira, incluindo roçagem e queima | C8: m2 | D8: 2581 | E8: 4.38 | G8: 11304.78 | I8: =G8/$K$5 -> 0.0030506622
A9: 01.01.001.002 | B9: Destocamento de árvores de porte médio e raízes profundas, sem auxílio mecânico | C9: un | D9: 64.53 | E9: 217.25 | G9: 14018.06 | I9: =G9/$K$5 -> 0.0037828569
A10: 01.01.001.003 | B10: Coleta e carga manuais de entulho | C10: m3 | D10: 774.3 | E10: 17.54 | G10: 13581.22 | I10: =G10/$K$5 -> 0.0036649731
A11: 01.01.001.004 | B11: Transporte com caminhão basculante de 6 m³, em via urbana em revestimento primário (unidade: txkm). af_07/2020 | C11: txkm | D11: 15563.43 | E11: 2.05 | G11: 31905.03 | I11: =G11/$K$5 -> 0.0086097623
A12: 01.01.002 | B12: DEMOLIÇÃO DE EDIFICAÇÕES | G12: =SUM(G13:G18) -> 6768.76 | I12: =G12/$K$5 -> 0.0018265902
A13: 01.01.002.001 | B13: Demolição de alvenaria de bloco furado, de forma manual, sem reaproveitamento. af_09/2023 | C13: m3 | D13: 42 | E13: 54.08 | G13: 2271.36 | I13: =G13/$K$5 -> 0.00061294002
A14: 01.01.002.002 | B14: Demolição de lajes, em concreto armado, de forma mecanizada com martelete, sem reaproveitamento. af_09/2023 | C14: m3 | D14: 10.5 | E14: 78.37 | G14: 822.88 | I14: =G14/$K$5 -> 0.00022205907
A15: 01.01.002.003 | B15: Demolição de pilares e vigas em concreto armado, de forma mecanizada com martelete, sem reaproveitamento. af_09/2023 | C15: m3 | D15: 3.68 | E15: 168.28 | G15: 618.43 | I15: =G15/$K$5 -> 0.00016688702
A16: 01.01.002.004 | B16: Demolição de revestimento cerâmico, de forma mecanizada com martelete, sem reaproveitamento. af_09/2023 | C16: m2 | D16: 56 | E16: 6.36 | G16: 356.16 | I16: =G16/$K$5 -> 9.6111896e-05
A17: 01.01.002.005 | B17: Coleta e carga manuais de entulho | C17: m3 | D17: 56 | E17: 17.54 | G17: 982.24 | I17: =G17/$K$5 -> 0.00026506331
A18: 01.01.002.006 | B18: Transporte com caminhão basculante de 6 m³, em via urbana em revestimento primário (unidade: txkm). af_07/2020 | C18: txkm | D18: 837.9 | E18: 2.05 | G18: 1717.69 | I18: =G18/$K$5 -> 0.00046352887
A19: 01.02 | B19: ESTRUTURAS DE CONTENÇÃO | H19: =G20+G22+G37 -> 3607402.4 | I19: =H19/$K$5 -> 0.97347902
A20: 01.02.001 | B20: SOLO GRAMPEADO | G20: =G21 -> 1135853.6 | I20: =G20/$K$5 -> 0.30651686
A21: 01.02.001.001 | B21: Solo Grampeado para controlede erosão com malha hexagonal de dupla torção, revestimento em PVC e com resistência de puncionamento de 105 KN e resistência à tração de 89 KN/m. Associada a geomanta tridimensional verde. | C21: m2 | D21: 1505 | E21: 754.72 | G21: 1135853.6 | I21: =G21/$K$5 -> 0.30651686
A22: 01.02.002 | B22: MURO DE ARRIMO | G22: =SUM(G23:G36) -> 2159643.1 | I22: =G22/$K$5 -> 0.58279256
A23: 01.02.002.001 | B23: Concretagem de pilares, fck = 25 mpa, com uso de bomba - lançamento, adensamento e acabamento. af_02/2022_ps | C23: m3 | D23: 390 | E23: 641.26 | G23: 250091.4 | I23: =G23/$K$5 -> 0.067488653
A24: 01.02.002.002 | B24: Armação de cinta de alvenaria estrutural; diâmetro de 16,0 mm. af_09/2021 | C24: kg | D24: 9750 | E24: 8.64 | G24: 84240 | I24: =G24/$K$5 -> 0.022732665
A25: 01.02.002.003 | B25: Armação de verga e contraverga de alvenaria estrutural; diâmetro de 16,0 mm. af_09/2021 | C25: kg | D25: 17550 | E25: 9.66 | G25: 169533 | I25: =G25/$K$5 -> 0.045749489
A26: 01.02.002.004 | B26: Armação vertical de alvenaria estrutural; diâmetro de 16,0 mm. af_09/2021 | C26: kg | D26: 17550 | E26: 8.84 | G26: 155142 | I26: =G26/$K$5 -> 0.041865992
A27: 01.02.002.005 | B27: Reaterro manual de valas, com compactador de solos de percussão. af_08/2023 | C27: m3 | D27: 780 | E27: 25.13 | G27: 19601.4 | I27: =G27/$K$5 -> 0.0052895545
A28: 01.02.002.006 | B28: Grauteamento de cinta intermediária ou de contraverga em alvenaria estrutural. af_09/2021 | C28: m3 | D28: 19.5 | E28: 900.01 | G28: 17550.19 | I28: =G28/$K$5 -> 0.0047360233
A29: 01.02.002.007 | B29: Grauteamento de cinta superior ou de verga em alvenaria estrutural. af_09/2021 | C29: m3 | D29: 19.5 | E29: 1002.12 | G29: 19541.34 | I29: =G29/$K$5 -> 0.0052733469
A30: 01.02.002.008 | B30: Grauteamento vertical em alvenaria estrutural. af_09/2021 | C30: m3 | D30: 487.5 | E30: 1037.21 | G30: 505639.88 | I30: =G30/$K$5 -> 0.13644993
A31: 01.02.002.009 | B31: Tubo pvc rigido soldavel, serie reforçada, p/esgoto e aguas pluviais, d= 100mm | C31: m | D31: 487.5 | E31: 45.3 | G31: 22083.75 | I31: =G31/$K$5 -> 0.0059594314
A32: 01.02.002.010 | B32: Alvenaria de blocos de concreto estrutural 14x19x39 cm (espessura 14 cm), fbk = 14 mpa, utilizando colher de pedreiro. af_10/2022 | C32: m2 | D32: 975 | E32: 106.17 | G32: 103515.75 | I32: =G32/$K$5 -> 0.027934341
A33: 01.02.002.011 | B33: Escavação mecanizada para viga baldrame ou sapata corrida com mini-escavadeira (incluindo escavação para colocação de fôrmas). af_01/2024 | C33: m3 | D33: 780 | E33: 56.85 | G33: 44343 | I33: =G33/$K$5 -> 0.011966223
A34: 01.02.002.012 | B34: Fabricação, montagem e desmontagem de fôrma para sapata corrida, em madeira serrada, e=25 mm, 4 utilizações. af_01/2024 | C34: m2 | D34: 780 | E34: 76.84 | G34: 59935.2 | I34: =G34/$K$5 -> 0.016173871
... A36: 01.02.002.014 | B36: Concretagem de sapata corrida, fck 30 mpa, com uso de bomba - lançamento, adensamento e acabamento. af_01/2024 | C36: m3 | D36: 780 | E36: 734.02 | G36: 572535.6 | I36: =G36/$K$5 -> 0.15450214
A37: 01.02.003 | B37: CORTINA ATIRANTADA | G37: =G38+G44 -> 311905.69 | I37: =G37/$K$5 -> 0.084169607
A38: 01.02.003.001 | B38: FUNDAÇÃO - ESTACAS | G38: =SUM(G39:G43) -> 143856.18 | I38: =G38/$K$5 -> 0.038820447
A39: 01.02.003.001.001 | B39: Perfuratriz com torre metálica para execução de estaca hélice contínua, profundidade máxima de 30 m, diâmetro máximo de 800 mm, potência instalada de 268 hp, mesa rotativa com torque máximo de 170 knm - depreciação. af_06/2015 | C39: h | D39: 171.7 | E39: 238.49 | G39: 40948.73 | I39: =G39/$K$5 -> 0.011050259
A40: 01.02.003.001.002 | B40: Execução de estaca hélice contínua monitorada Ø 500mm, concreto fck=40Mpa, inclusive aço, bombeamento; exclusive mobilização e desmobilização de equipamento e bate-estacas | C40: m | D40: 303 | E40: 337.82 | G40: 102359.46 | I40: =G40/$K$5 -> 0.02762231
A41: 01.02.003.001.003 | B41: Transporte horizontal com carrinho de mão, de sacos de 50 kg (unidade: kgxkm). af_07/2019 | C41: kgxkm | D41: 580.75 | E41: 0.76 | G41: 441.37 | I41: =G41/$K$5 -> 0.00011910632
A42: 01.02.003.001.004 | B42: Carga manual de material de 1ª categoria | C42: m3 | D42: 10.1 | E42: 10.49 | G42: 105.95 | I42: =G42/$K$5 -> 2.8591238e-05
...

Sheet 04_Seringal
A1: PMRR DE ILHÉUS
A3: Empreendimento: 000028 - Alto do Seringal (Bairro Esperança) | G3: VALOR TOTAL
A4: ITEM | B4: DESCRIÇÃO DO ITEM | C4: UNID | D4: QUANT | E4: PREÇO UNIT | G4: Valor Parcial | I4: Parcial (%) | K4: Soma | L4: (%)
A5: 1 | B5: Setor de Risco A2S1R3 (Contenções e Demolições) | K5: =SUM(H5:H30) -> 459537.89 | L5: =K5/$G$138 -> 0.17470557
A6: 01.01 | B6: SERVIÇOS PRELIMINARES | H6: =G7 -> 5596.69 | I6: =H6/$K$5 -> 0.012178952
A7: 01.01.001 | B7: LIMPEZA DE TERRENO (204,0 m²) | G7: =SUM(G8:G11) -> 5596.69 | I7: =G7/$K$5 -> 0.012178952
A8: 01.01.001.001 | B8: Limpeza manual de terreno com vegetação rasteira, incluindo roçagem e queima | C8: m2 | D8: 204 | E8: 4.38 | G8: 893.52 | I8: =G8/$K$5 -> 0.0019443881
A9: 01.01.001.002 | B9: Destocamento de árvores de porte médio e raízes profundas, sem auxílio mecânico | C9: un | D9: 5.1 | E9: 217.25 | G9: 1107.97 | I9: =G9/$K$5 -> 0.0024110525
A10: 01.01.001.003 | B10: Coleta e carga manuais de entulho | C10: m3 | D10: 61.2 | E10: 17.54 | G10: 1073.45 | I10: =G10/$K$5 -> 0.0023359336
A11: 01.01.001.004 | B11: Transporte com caminhão basculante de 6 m³, em via urbana em revestimento primário (unidade: txkm). af_07/2020 | C11: txkm | D11: 1230.12 | E11: 2.05 | G11: 2521.75 | I11: =G11/$K$5 -> 0.005487578
A12: 01.02 | B12: ESTRUTURAS DE CONTENÇÃO | H12: =G13 -> 451863.8 | I12: =H12/$K$5 -> 0.98330042
A13: 01.02.001 | B13: MURO DE ARRIMO (204,0 m²) | G13: =SUM(G14:G27) -> 451863.8 | I13: =G13/$K$5 -> 0.98330042
A14: 01.02.001.001 | B14: Concretagem de pilares, fck = 25 mpa, com uso de bomba - lançamento, adensamento e acabamento. af_02/2022_ps | C14: m3 | D14: 81.6 | E14: 641.26 | G14: 52326.82 | I14: =G14/$K$5 -> 0.11386835
A15: 01.02.001.002 | B15: Armação de cinta de alvenaria estrutural; diâmetro de 16,0 mm. af_09/2021 | C15: kg | D15: 2040 | E15: 8.64 | G15: 17625.6 | I15: =G15/$K$5 -> 0.038355053
A16: 01.02.001.003 | B16: Armação de verga e contraverga de alvenaria estrutural; diâmetro de 16,0 mm. af_09/2021 | C16: kg | D16: 3672 | E16: 9.66 | G16: 35471.52 | I16: =G16/$K$5 -> 0.077189544
A17: 01.02.001.004 | B17: Armação vertical de alvenaria estrutural; diâmetro de 16,0 mm. af_09/2021 | C17: kg | D17: 3672 | E17: 8.84 | G17: 32460.48 | I17: =G17/$K$5 -> 0.070637222
A18: 01.02.001.005 | B18: Reaterro manual de valas, com compactador de solos de percussão. af_08/2023 | C18: m3 | D18: 163.2 | E18: 25.13 | G18: 4101.22 | I18: =G18/$K$5 -> 0.0089246613
A19: 01.02.001.006 | B19: Grauteamento de cinta intermediária ou de contraverga em alvenaria estrutural. af_09/2021 | C19: m3 | D19: 4.08 | E19: 900.01 | G19: 3672.04 | I19: =G19/$K$5 -> 0.007990723
A20: 01.02.001.007 | B20: Grauteamento de cinta superior ou de verga em alvenaria estrutural. af_09/2021 | C20: m3 | D20: 4.08 | E20: 1002.12 | G20: 4088.65 | I20: =G20/$K$5 -> 0.0088973077
A21: 01.02.001.008 | B21: Grauteamento vertical em alvenaria estrutural. af_09/2021 | C21: m3 | D21: 102 | E21: 1037.21 | G21: 105795.42 | I21: =G21/$K$5 -> 0.23022132
A22: 01.02.001.009 | B22: Tubo pvc rigido soldavel, serie reforçada, p/esgoto e aguas pluviais, d= 100mm | C22: m | D22: 102 | E22: 45.3 | G22: 4620.6 | I22: =G22/$K$5 -> 0.010054884
A23: 01.02.001.010 | B23: Alvenaria de blocos de concreto estrutural 14x19x39 cm (espessura 14 cm), fbk = 14 mpa, utilizando colher de pedreiro. af_10/2022 | C23: m2 | D23: 204 | E23: 106.17 | G23: 21658.68 | I23: =G23/$K$5 -> 0.047131435
A24: 01.02.001.011 | B24: Escavação mecanizada para viga baldrame ou sapata corrida com mini-escavadeira (incluindo escavação para colocação de fôrmas). af_01/2024 | C24: m3 | D24: 163.2 | E24: 56.85 | G24: 9277.92 | I24: =G24/$K$5 -> 0.020189674
A25: 01.02.001.012 | B25: Fabricação, montagem e desmontagem de fôrma para sapata corrida, em madeira serrada, e=25 mm, 4 utilizações. af_01/2024 | C25: m2 | D25: 163.2 | E25: 76.84 | G25: 12540.29 | I25: =G25/$K$5 -> 0.027288914
... A27: 01.02.001.014 | B27: Concretagem de sapata corrida, fck 30 mpa, com uso de bomba - lançamento, adensamento e acabamento. af_01/2024 | C27: m3 | D27: 163.2 | E27: 734.02 | G27: 119792.06 | I27: =G27/$K$5 -> 0.2606794
A28: 01.03 | B28: DRENAGEM DAS ESTRUTURAS DE CONTENÇÃO | H28: =G29 -> 2077.4 | I28: =H28/$K$5 -> 0.0045206283
A29: 01.03.001 | B29: CANALETA (68,0 m) | G29: =G30 -> 2077.4 | I29: =G29/$K$5 -> 0.0045206283
A30: 01.03.001.001 | B30: Canaleta meia cana pré-moldada de concreto (d = 20 cm) - fornecimento e instalação. af_08/2021 | C30: m | D30: 68 | E30: 30.55 | G30: 2077.4 | I30: =G30/$K$5 -> 0.0045206283
A32: 2 | B32: Setor de Risco A3S1R4 (Contenções e Demolições) | K32: =SUM(H32:H92) -> 2170818.4 | L32: =K32/$G$138 -> 0.82529443
A33: 02.01 | B33: SERVIÇOS PRELIMINARES | H33: =G34+G39 -> 74293.39 | I33: =H33/$K$32 -> 0.034223678
A34: 02.01.001 | B34: LIMPEZA DE TERRENO (2063,0 m²) | G34: =SUM(G35:G38) -> 56597.89 | I34: =G34/$K$32 -> 0.026072144
A35: 02.01.001.001 | B35: Limpeza manual de terreno com vegetação rasteira, incluindo roçagem e queima | C35: m2 | D35: 2063 | E35: 4.38 | G35: 9035.94 | I35: =G35/$K$32 -> 0.0041624578
A36: 02.01.001.002 | B36: Destocamento de árvores de porte médio e raízes profundas, sem auxílio mecânico | C36: un | D36: 51.58 | E36: 217.25 | G36: 11204.67 | I36: =G36/$K$32 -> 0.0051614957
A37: 02.01.001.003 | B37: Coleta e carga manuais de entulho | C37: m3 | D37: 618.9 | E37: 17.54 | G37: 10855.51 | I37: =G37/$K$32 -> 0.0050006532
A38: 02.01.001.004 | B38: Transporte com caminhão basculante de 6 m³, em via urbana em revestimento primário (unidade: txkm). af_07/2020 | C38: txkm | D38: 12439.89 | E38: 2.05 | G38: 25501.77 | I38: =G38/$K$32 -> 0.011747537
A39: 02.01.002 | B39: DEMOLIÇÃO DE EDIFICAÇÕES (183,0 m²) | G39: =SUM(G40:G45) -> 17695.5 | I39: =G39/$K$32 -> 0.0081515339
A40: 02.01.002.001 | B40: Demolição de alvenaria de bloco furado, de forma manual, sem reaproveitamento. af_09/2023 | C40: m3 | D40: 109.8 | E40: 54.08 | G40: 5937.98 | I40: =G40/$K$32 -> 0.0027353647
A41: 02.01.002.002 | B41: Demolição de lajes, em concreto armado, de forma mecanizada com martelete, sem reaproveitamento. af_09/2023 | C41: m3 | D41: 27.45 | E41: 78.37 | G41: 2151.26 | I41: =G41/$K$32 -> 0.0009909903
A42: 02.01.002.003 | B42: Demolição de pilares e vigas em concreto armado, de forma mecanizada com martelete, sem reaproveitamento. af_09/2023 | C42: m3 | D42: 9.61 | E42: 168.28 | G42: 1616.75 | I42: =G42/$K$32 -> 0.00074476519
A43: 02.01.002.004 | B43: Demolição de revestimento cerâmico, de forma mecanizada com martelete, sem reaproveitamento. af_09/2023 | C43: m2 | D43: 146.4 | E43: 6.36 | G43: 931.1 | I43: =G43/$K$32 -> 0.00042891657
...

Sheet 05_Vila Freitas
A1: PMRR DE ILHÉUS
A3: Empreendimento: 000016 - Alto Vila Freitas (Bairro Esperança) | G3: VALOR TOTAL
A4: ITEM | B4: DESCRIÇÃO DO ITEM | C4: UNID | D4: QUANT | E4: PREÇO UNIT | G4: Valor Parcial | I4: Parcial (%) | K4: Soma | L4: (%)
A5: 1 | B5: Setor de Risco A1S1R3 (Contenções e Demolições) | K5: =SUM(H5:H37) -> 800252.69 | L5: 1
A6: 01.01 | B6: SERVIÇOS PRELIMINARES | H6: =G7+G12 -> 18665.827 | I6: =H6/$K$5 -> 0.023324916
A7: 01.01.001 | B7: LIMPEZA DE TERRENO | G7: =SUM(G8:G11) -> 11897.07 | I7: =G7/$K$5 -> 0.014866642
A8: 01.01.001.001 | B8: Limpeza manual de terreno com vegetação rasteira, incluindo roçagem e queima | C8: m2 | D8: 342 | E8: 5.55 | G8: 1898.1 | I8: =G8/$K$5 -> 0.0023718758
A9: 01.01.001.002 | B9: Destocamento de árvores de porte médio e raízes profundas, sem auxílio mecânico | C9: un | D9: 8.55 | E9: 275.47 | G9: 2355.27 | I9: =G9/$K$5 -> 0.0029431579
A10: 01.01.001.003 | B10: Coleta e carga manuais de entulho | C10: m3 | D10: 102.6 | E10: 22.24 | G10: 2281.82 | I10: =G10/$K$5 -> 0.0028513744
A11: 01.01.001.004 | B11: Transporte com caminhão basculante de 6 m³, em via urbana em revestimento primário (unidade: txkm). af_07/2020 | C11: txkm | D11: 2062.26 | E11: 2.6 | G11: 5361.88 | I11: =G11/$K$5 -> 0.0067002336
A12: 01.01.002 | B12: DEMOLIÇÃO DE EDIFICAÇÕES | G12: =SUM(G13:G18) -> 6768.757 | I12: =G12/$K$5 -> 0.0084582746
A13: 01.01.002.001 | B13: Demolição de alvenaria de bloco furado, de forma manual, sem reaproveitamento. af_09/2023 | C13: m3 | D13: 20 | E13: 68.57 | G13: 1371.4 | I13: =G13/$K$5 -> 0.0017137087
A14: 01.01.002.002 | B14: Demolição de lajes, em concreto armado, de forma mecanizada com martelete, sem reaproveitamento. af_09/2023 | C14: m3 | D14: 7.5 | E14: 99.37 | G14: 745.27 | I14: =G14/$K$5 -> 0.00093129334
A15: 01.01.002.003 | B15: Demolição de pilares e vigas em concreto armado, de forma mecanizada com martelete, sem reaproveitamento. af_09/2023 | C15: m3 | D15: 3.68 | E15: 213.38 | G15: 784.17 | I15: =G15/$K$5 -> 0.00097990298
A16: 01.01.002.004 | B16: Demolição de revestimento cerâmico, de forma mecanizada com martelete, sem reaproveitamento. af_09/2023 | C16: m2 | D16: 56 | E16: 8.06 | G16: 451.36 | I16: =G16/$K$5 -> 0.00056402185
A17: 01.01.002.005 | B17: Coleta e carga manuais de entulho | C17: m3 | D17: 56 | E17: 22.24 | G17: 1245.44 | I17: =G17/$K$5 -> 0.0015563084
A18: 01.01.002.006 | B18: Transporte com caminhão basculante de 6 m³, em via urbana em revestimento primário (unidade: txkm). af_07/2020 | C18: txkm | D18: 835.045 | E18: 2.6 | G18: =D18*E18 -> 2171.117 | I18: =G18/$K$5 -> 0.0027130393
A19: 01.02 | B19: ESTRUTURAS DE CONTENÇÃO | H19: =G20 -> 777170.5 | I19: =H19/$K$5 -> 0.97115638
A20: 01.02.001 | B20: MURO DE ARRIMO | G20: =SUM(G21:G34) -> 777170.5 | I20: =G20/$K$5 -> 0.97115638
A21: 01.02.001.001 | B21: Concretagem de pilares, fck = 25 mpa, com uso de bomba - lançamento, adensamento e acabamento. af_02/2022_ps | C21: m3 | D21: 118 | E21: 813.12 | G21: =D21*E21 -> 95948.16 | I21: =G21/$K$5 -> 0.11989733
